Workbook

Sheet PLA - Vektregistrering
D2: Plasttype: PLA | H2: Første testpinne i hvert sett skal ikke skylles
B4: Dato | D4: 28/1
B6: Prøve ID | C6: Startvekt | D6: Prøve ID | E6: Startvekt
B7: A-0-1 | C7: 1.449 | D7: A-0-2 | E7: 1.4502
B8: A-0-1 | C8: 1.4505 | D8: A-0-2 | E8: 1.4489
B9: A-0-1 | C9: 1.4512 | D9: A-0-2 | E9: 1.4451
B10: A-0-1 | C10: 1.4496 | D10: A-0-2 | E10: 1.4458
B11: A-0-1 | C11: 1.4508 | D11: A-0-2 | E11: 1.4465
B13: Temp 20C | L13: Temp 40C | V13: Temp 60C
B15: Tørr | G15: Våt | L15: Tørr | Q15: Våt | V15: Tørr | AA15: Våt
B17: Dato | C17: 26/1 | D17: 17/2 | E17: 19/2 | G17: Dato | H17: 26/1 | I17: 17/2 | L17: Dato | M17: 26/1 | N17: 17/2 | O17: 19/2 | Q17: Dato | R17: 26/1 | S17: 17/2 | V17: Dato | W17: 26/1 | X17: 17/2 | Y17: 19/2 | AA17: Dato | AB17: 26/1 | AC17: 17/2
B19: Prøve ID | C19: Startvekt | D19: Sluttvekt | E19: Tørrvekt | G19: Prøve ID | H19: Startvekt | I19: Sluttvekt | L19: Prøve ID | M19: Startvekt | N19: Sluttvekt | O19: Tørrvekt | Q19: Prøve ID | R19: Startvekt | S19: Sluttvekt | V19: Prøve ID | W19: Startvekt | X19: Sluttvekt | Y19: Tørrvekt | AA19: Prøve ID | AB19: Startvekt | AC19: Sluttvekt
A20: ikke skylt | B20: A-1-1 | C20: 1.4414 | D20: 1.4647 | E20: 1.4462 | F20: ikke skylt | G20: A-1-2 | H20: 1.442 | I20: 1.4692 | K20: ikke skylt | L20: A-2-1 | M20: 1.4441 | N20: 1.4874 | O20: 1.4563 | P20: ikke skylt | Q20: A-2-2 | R20: 1.441 | S20: 1.4741 | U20: ikke skylt | V20: A-3-1 | W20: 1.4464 | X20: 1.5093 | Y20: 1.4637 | Z20: ikke skylt | AA20: A-3-2 | AB20: 1.4429 | AC20: 1.4849
A21: skylt og tørket | B21: A-1-1 | C21: 1.4429 | D21: 1.4794 | E21: 1.4507 | F21: skylt og tørket | G21: A-1-2 | H21: 1.443 | I21: 1.4751 | K21: skylt og tørket | L21: A-2-1 | M21: 1.4447 | N21: 1.4892 | O21: 1.4538 | P21: skylt og tørket | Q21: A-2-2 | R21: 1.4462 | S21: 1.4795 | U21: skylt og tørket | V21: A-3-1 | W21: 1.4423 | X21: 1.5037 | Y21: 1.452 | Z21: skylt og tørket | AA21: A-3-2 | AB21: 1.4505 | AC21: 1.5068
A22: skylt og tørket | B22: A-1-1 | C22: 1.444 | D22: 1.4742 | E22: 1.4469 | F22: skylt og tørket | G22: A-1-2 | H22: 1.4459 | I22: 1.4751 | K22: skylt og tørket | L22: A-2-1 | M22: 1.448 | N22: 1.4855 | O22: 1.456 | P22: skylt og tørket | Q22: A-2-2 | R22: 1.4473 | S22: 1.4915 | U22: skylt og tørket | V22: A-3-1 | W22: 1.4433 | X22: 1.5024 | Y22: 1.4571 | Z22: skylt og tørket | AA22: A-3-2 | AB22: 1.4454 | AC22: 1.5067
A23: skylt og tørket | B23: A-1-1 | C23: 1.4417 | D23: 1.4691 | E23: 1.4472 | F23: skylt og tørket | G23: A-1-2 | H23: 1.4458 | I23: 1.4779 | K23: skylt og tørket | L23: A-2-1 | M23: 1.4416 | N23: 1.483 | O23: 1.4496 | P23: skylt og tørket | Q23: A-2-2 | R23: 1.4514 | S23: 1.5037 | U23: skylt og tørket | V23: A-3-1 | W23: 1.4481 | X23: 1.5107 | Y23: 1.4621 | Z23: skylt og tørket | AA23: A-3-2 | AB23: 1.4493 | AC23: 1.4997
A24: skylt og tørket | B24: A-1-1 | C24: 1.4428 | D24: 1.4726 | E24: 1.4456 | F24: skylt og tørket | G24: A-1-2 | H24: 1.4437 | I24: 1.4847 | K24: skylt og tørket | L24: A-2-1 | M24: 1.441 | N24: 1.4707 | O24: 1.4479 | P24: skylt og tørket | Q24: A-2-2 | R24: 1.4505 | S24: 1.4936 | U24: skylt og tørket | V24: A-3-1 | W24: 1.4455 | X24: 1.508 | Y24: 1.4586 | Z24: skylt og tørket | AA24: A-3-2 | AB24: 1.4519 | AC24: 1.506
B27: Dato | C27: 46048 | D27: 46090 | E27: 46092 | G27: Dato | H27: 26/1 | I27: 46090 | L27: Dato | M27: 26/1 | N27: 46090 | O27: 46092 | Q27: Dato | R27: 26/1 | S27: 46090 | V27: Dato | W27: 26/1 | X27: 46090 | Y27: 46092 | AA27: Dato | AB27: 26/1 | AC27: 46090
B29: Prøve ID | C29: Startvekt | D29: Sluttvekt | E29: Tørrvekt | G29: Prøve ID | H29: Startvekt | I29: Sluttvekt | L29: Prøve ID | M29: Startvekt | N29: Sluttvekt | O29: Tørrvekt | Q29: Prøve ID | R29: Startvekt | S29: Sluttvekt | V29: Prøve ID | W29: Startvekt | X29: Sluttvekt | Y29: Tørrvekt | AA29: Prøve ID | AB29: Startvekt | AC29: Sluttvekt
A30: ikke skylt | B30: A-1-3 | C30: 1.4474 | D30: 1.4872 | E30: 1.4516 | G30: A-1-4 | H30: 1.4449 | I30: 1.4863 | K30: ikke skylt | L30: A-2-3 | M30: 1.4491 | N30: 1.5055 | O30: 1.4537 | P30: ikke skylt | Q30: A-2-4 | R30: 1.4418 | S30: 1.5126 | U30: ikke skylt | V30: A-3-3 | W30: 1.4429 | X30: 1.5103 | Y30: 1.3338 | Z30: ikke skylt | AA30: A-3-4 | AB30: 1.4462 | AC30: 1.51
A31: skylt og tørket | B31: A-1-3 | C31: 1.4428 | D31: 1.4836 | E31: 1.4501 | G31: A-1-4 | H31: 1.4469 | I31: 1.4843 | K31: skylt og tørket | L31: A-2-3 | M31: 1.4473 | N31: 1.493 | O31: 1.4542 | P31: skylt og tørket | Q31: A-2-4 | R31: 1.4457 | S31: 1.4917 | U31: skylt og tørket | V31: A-3-3 | W31: 1.4427 | X31: 1.5071 | Y31: 1.3126 | Z31: skylt og tørket | AA31: A-3-4 | AB31: 1.4461 | AC31: 1.5166
A32: skylt og tørket | B32: A-1-3 | C32: 1.4435 | D32: 1.4822 | E32: 1.4499 | G32: A-1-4 | H32: 1.4467 | I32: 1.486 | K32: skylt og tørket | L32: A-2-3 | M32: 1.4475 | N32: 1.4926 | O32: 1.4533 | P32: skylt og tørket | Q32: A-2-4 | R32: 1.4461 | S32: 1.4928 | U32: skylt og tørket | V32: A-3-3 | W32: 1.4503 | X32: 1.5164 | Y32: 1.3629 | Z32: skylt og tørket | AA32: A-3-4 | AB32: 1.4468 | AC32: 1.5182
A33: skylt og tørket | B33: A-1-3 | C33: 1.4445 | D33: 1.481 | E33: 1.4511 | G33: A-1-4 | H33: 1.4462 | I33: 1.4838 | K33: skylt og tørket | L33: A-2-3 | M33: 1.4445 | N33: 1.5062 | O33: 1.4547 | P33: skylt og tørket | Q33: A-2-4 | R33: 1.4514 | S33: 1.4951 | U33: skylt og tørket | V33: A-3-3 | W33: 1.4452 | X33: 1.5166 | Y33: 1.3238 | Z33: skylt og tørket | AA33: A-3-4 | AB33: 1.4469 | AC33: 1.5153
A34: skylt og tørket | B34: A-1-3 | C34: 1.444 | D34: 1.484 | E34: 1.4495 | G34: A-1-4 | H34: 1.4453 | I34: 1.4743 | K34: skylt og tørket | L34: A-2-3 | M34: 1.4447 | N34: 1.4884 | O34: 1.452 | P34: skylt og tørket | Q34: A-2-4 | R34: 1.4465 | S34: 1.5019 | U34: skylt og tørket | V34: A-3-3 | W34: 1.4457 | X34: 1.52 | Y34: 1.3519 | Z34: skylt og tørket | AA34: A-3-4 | AB34: 1.444 | AC34: 1.5089
B37: Dato | C37: 26/1 | D37: 30/3 | E37: 46113 | G37: Dato | H37: 26/1 | I37: 30/3 | L37: Dato | M37: 26/1 | N37: 30/3 | O37: 46113 | Q37: Dato | R37: 26/1 | S37: 30/3 | V37: Dato | W37: 26/1 | X37: 30/3 | Y37: 46113 | AA37: Dato | AB37: 26/1 | AC37: 30/3
B39: Prøve ID | C39: Startvekt | D39: Sluttvekt | E39: Tørrvekt | G39: Prøve ID | H39: Startvekt | I39: Sluttvekt | L39: Prøve ID | M39: Startvekt | N39: Sluttvekt | O39: Tørrvekt | Q39: Prøve ID | R39: Startvekt | S39: Sluttvekt | V39: Prøve ID | W39: Startvekt | X39: Sluttvekt | Y39: Tørrvekt | AA39: Prøve ID | AB39: Startvekt | AC39: Sluttvekt
A40: ikke skylt | B40: A-1-5 | C40: 1.4436 | D40: 1.4863 | E40: 1.4482 | G40: A-1-6 | H40: 1.449 | I40: 1.4992 | K40: ikke skylt | L40: A-2-5 | M40: 1.4501 | N40: 1.5012 | O40: 1.4545 | Q40: A-2-6 | R40: 1.4426 | S40: 1.5385 | U40: ikke skylt | V40: A-3-5 | W40: 1.4498 | X40: Smulder | Z40: ikke skylt | AA40: A-3-6 | AB40: 1.4441 | AC40: Smulder
A41: skylt og tørket | B41: A-1-5 | C41: 1.441 | D41: 1.4772 | E41: 1.447 | G41: A-1-6 | H41: 1.4432 | I41: 1.4816 | K41: skylt og tørket | L41: A-2-5 | M41: 1.444 | N41: 1.7134 | O41: 1.455 | Q41: A-2-6 | R41: 1.444 | S41: 1.5078 | U41: skylt og tørket | V41: A-3-5 | W41: 1.4462 | X41: Smulder | Z41: skylt og tørket | AA41: A-3-6 | AB41: 1.4413 | AC41: Smulder
A42: skylt og tørket | B42: A-1-5 | C42: 1.444 | D42: 1.5213 | E42: 1.4491 | G42: A-1-6 | H42: 1.4419 | I42: 1.4813 | K42: skylt og tørket | L42: A-2-5 | M42: 1.4401 | N42: 1.4853 | O42: 1.4516 | Q42: A-2-6 | R42: 1.445 | S42: 1.5019 | U42: skylt og tørket | V42: A-3-5 | W42: 1.4477 | X42: Smulder | Z42: skylt og tørket | AA42: A-3-6 | AB42: 1.4411 | AC42: Smulder
A43: skylt og tørket | B43: A-1-5 | C43: 1.4415 | D43: 1.4724 | E43: 1.4478 | G43: A-1-6 | H43: 1.4394 | I43: 1.4754 | K43: skylt og tørket | L43: A-2-5 | M43: 1.4461 | N43: 1.5355 | O43: 1.4546 | Q43: A-2-6 | R43: 1.4454 | S43: 1.4989 | U43: skylt og tørket | V43: A-3-5 | W43: 1.4426 | X43: Smulder | Z43: skylt og tørket | AA43: A-3-6 | AB43: 1.444 | AC43: Smulder
A44: skylt og tørket | B44: A-1-5 | C44: 1.4425 | D44: 1.4953 | E44: 1.4485 | G44: A-1-6 | H44: 1.4455 | I44: 1.505 | K44: skylt og tørket | L44: A-2-5 | M44: 1.4449 | N44: 1.4957 | O44: 1.4521 | Q44: A-2-6 | R44: 1.4448 | S44: 1.5091 | U44: skylt og tørket | V44: A-3-5 | W44: 1.4451 | X44: Smulder | Z44: skylt og tørket | AA44: A-3-6 | AB44: 1.4515 | AC44: Smulder
B47: Dato | C47: 26/1 | D47: 46133 | E47: 46135 | G47: Dato | H47: 26/1 | I47: 46133 | L47: Dato | M47: 26/1 | N47: 46133 | O47: 46135 | Q47: Dato | R47: 26/1 | S47: 46133 | V47: Dato | W47: 26/1 | X47: 46133 | Y47: 46135 | AA47: Dato | AB47: 26/1 | AC47: 46111
B49: Prøve ID | C49: Startvekt | D49: Sluttvekt | E49: Tørrvekt | G49: Prøve ID | H49: Startvekt | I49: Sluttvekt | L49: Prøve ID | M49: Startvekt | N49: Sluttvekt | O49: Tørrvekt | Q49: Prøve ID | R49: Startvekt | S49: Sluttvekt | V49: Prøve ID | W49: Startvekt | X49: Sluttvekt | Y49: Tørrvekt | AA49: Prøve ID | AB49: Startvekt | AC49: Sluttvekt
A50: ikke skylt | B50: A-1-7 | C50: 1.4457 | D50: 1.4985 | E50: 1.4542 | G50: A-1-8 | H50: 1.446 | I50: 1.4964 | K50: ikke skylt | L50: A-2-7 | M50: 1.4413 | N50: 1.5007 | O50: 1.4524 | Q50: A-2-8 | R50: 1.441 | S50: 1.49 | U50: ikke skylt | V50: A-3-7 | W50: 1.444 | X50: 1.3988 | Y50: 1.162 | Z50: ikke skylt | AA50: A-3-8 | AB50: 1.4438 | AC50: 1.3973
A51: skylt og tørket | B51: A-1-7 | C51: 1.4458 | D51: 1.5066 | E51: 1.455 | G51: A-1-8 | H51: 1.4426 | I51: 1.4937 | K51: skylt og tørket | L51: A-2-7 | M51: 1.4461 | N51: 1.5084 | O51: 1.4554 | Q51: A-2-8 | R51: 1.4448 | S51: 1.5096 | U51: skylt og tørket | V51: A-3-7 | W51: 1.4446 | X51: 1.3995 | Y51: 1.1694 | Z51: skylt og tørket | AA51: A-3-8 | AB51: 1.4461 | AC51: 1.3964
A52: skylt og tørket | B52: A-1-7 | C52: 1.4472 | D52: 1.5096 | E52: 1.455 | G52: A-1-8 | H52: 1.4465 | I52: 1.4992 | K52: skylt og tørket | L52: A-2-7 | M52: 1.4429 | N52: 1.4974 | O52: 1.452 | Q52: A-2-8 | R52: 1.4428 | S52: 1.5071 | U52: skylt og tørket | V52: A-3-7 | W52: 1.4445 | X52: 1.3995 | Y52: 1.1687 | Z52: skylt og tørket | AA52: A-3-8 | AB52: 1.4452 | AC52: 1.3982
A53: skylt og tørket | B53: A-1-7 | C53: 1.4431 | D53: 1.5061 | E53: 1.4569 | G53: A-1-8 | H53: 1.4412 | I53: 1.4938 | K53: skylt og tørket | L53: A-2-7 | M53: 1.4456 | N53: 1.5073 | O53: 1.4548 | Q53: A-2-8 | R53: 1.4446 | S53: 1.506 | U53: skylt og tørket | V53: A-3-7 | W53: 1.4522 | X53: 1.3873 | Y53: 1.1618 | Z53: skylt og tørket | AA53: A-3-8 | AB53: 1.4488 | AC53: 1.4007
A54: skylt og tørket | B54: A-1-7 | C54: 1.4452 | D54: 1.506 | E54: 1.4534 | G54: A-1-8 | H54: 1.4482 | I54: 1.5049 | K54: skylt og tørket | L54: A-2-7 | M54: 1.4433 | N54: 1.5091 | O54: 1.4521 | Q54: A-2-8 | R54: 1.446 | S54: 1.5121 | U54: skylt og tørket | V54: A-3-7 | W54: 1.4477 | X54: 1.393 | Y54: 1.1718 | Z54: skylt og tørket | AA54: A-3-8 | AB54: 1.4425 | AC54: 1.3965

Sheet PLA - Resultatberegninger
A1: Gjennomsnittlige verdier brukt i resultatpresentasjonen for PLA
A4: Uke | B4: Type plast | C4: Temperatur | D4: Tilstand | E4: Dato | F4: Prøve ID | G4: Startvekt | H4: Sluttvekt | I4: Tørket etter 48 timer | J4: Vektendring | K4: Gj.snittlig vektendring | L4: Max | M4: Min | N4: Permanent endring | O4: Gj.snittlig premanent endring | P4: Max | Q4: Min
A6: 20 °C
A7: 3 | B7: PLA | C7: 20 | D7: Tørr | E7: 46070 | F7: A-1-1_1 | G7: 1.4414 | H7: 1.4647 | I7: 1.4462 | J7: =SUM(H7-G7) -> 0.0233 | K7: =AVERAGE(J7:J11) -> 0.02944 | L7: =SUM(J8) -> 0.0365 | M7: =SUM(J7) -> 0.0233 | N7: =SUM(I7-G7) -> 0.0048 | O7: =AVERAGE(N7:N11) -> 0.00476 | P7: =SUM(N8) -> 0.0078 | Q7: =SUM(N11) -> 0.0028
A8: 3 | B8: PLA | C8: 20 | D8: Tørr | E8: 46070 | F8: A-1-1_2 | G8: 1.4429 | H8: 1.4794 | I8: 1.4507 | J8: =SUM(H8-G8) -> 0.0365 | N8: =SUM(I8-G8) -> 0.0078
A9: 3 | B9: PLA | C9: 20 | D9: Tørr | E9: 46070 | F9: A-1-1_3 | G9: 1.444 | H9: 1.4742 | I9: 1.4469 | J9: =SUM(H9-G9) -> 0.0302 | N9: =SUM(I9-G9) -> 0.0029
A10: 3 | B10: PLA | C10: 20 | D10: Tørr | E10: 46070 | F10: A-1-1_4 | G10: 1.4417 | H10: 1.4691 | I10: 1.4472 | J10: =SUM(H10-G10) -> 0.0274 | N10: =SUM(I10-G10) -> 0.0055
A11: 3 | B11: PLA | C11: 20 | D11: Tørr | E11: 46070 | F11: A-1-1_5 | G11: 1.4428 | H11: 1.4726 | I11: 1.4456 | J11: =SUM(H11-G11) -> 0.0298 | N11: =SUM(I11-G11) -> 0.0028
A12: 3 | B12: PLA | C12: 20 | D12: Våt | E12: 46070 | F12: A-1-2_1 | G12: 1.442 | H12: 1.4692 | J12: =SUM(H12-G12) -> 0.0272 | K12: =AVERAGE(J12:J16) -> 0.03232 | L12: =SUM(J16) -> 0.041 | M12: =SUM(J12) -> 0.0272
A13: 3 | B13: PLA | C13: 20 | D13: Våt | E13: 46070 | F13: A-1-2_2 | G13: 1.443 | H13: 1.4751 | J13: =SUM(H13-G13) -> 0.0321
A14: 3 | B14: PLA | C14: 20 | D14: Våt | E14: 46070 | F14: A-1-2_3 | G14: 1.4459 | H14: 1.4751 | J14: =SUM(H14-G14) -> 0.0292
A15: 3 | B15: PLA | C15: 20 | D15: Våt | E15: 46070 | F15: A-1-2_4 | G15: 1.4458 | H15: 1.4779 | J15: =SUM(H15-G15) -> 0.0321
A16: 3 | B16: PLA | C16: 20 | D16: Våt | E16: 46070 | F16: A-1-2_5 | G16: 1.4437 | H16: 1.4847 | J16: =SUM(H16-G16) -> 0.041
A17: 6 | B17: PLA | C17: 20 | D17: Tørr | E17: 46090 | F17: A-1-3_1 | G17: 1.4474 | H17: 1.4872 | I17: 1.4516 | J17: =H17-G17 -> 0.0398 | K17: =AVERAGE(J17:J21) -> 0.03916 | L17: =SUM(J18) -> 0.0408 | M17: =SUM(J20) -> 0.0365 | N17: =SUM(I17-G17) -> 0.0042 | O17: =AVERAGE(N17:N21) -> 0.006 | P17: 0.0073 | Q17: 0.0042
A18: 6 | B18: PLA | C18: 20 | D18: Tørr | E18: 46090 | F18: A-1-3_2 | G18: 1.4428 | H18: 1.4836 | I18: 1.4501 | J18: =H18-G18 -> 0.0408 | N18: =SUM(I18-G18) -> 0.0073
A19: 6 | B19: PLA | C19: 20 | D19: Tørr | E19: 46090 | F19: A-1-3_3 | G19: 1.4435 | H19: 1.4822 | I19: 1.4499 | J19: =H19-G19 -> 0.0387 | N19: =SUM(I19-G19) -> 0.0064
A20: 6 | B20: PLA | C20: 20 | D20: Tørr | E20: 46090 | F20: A-1-3_4 | G20: 1.4445 | H20: 1.481 | I20: 1.4511 | J20: =H20-G20 -> 0.0365 | N20: =SUM(I20-G20) -> 0.0066
A21: 6 | B21: PLA | C21: 20 | D21: Tørr | E21: 46090 | F21: A-1-3_5 | G21: 1.444 | H21: 1.484 | I21: 1.4495 | J21: =H21-G21 -> 0.04 | N21: =SUM(I21-G21) -> 0.0055
A22: 6 | B22: PLA | C22: 20 | D22: Våt | E22: 46090 | F22: A-1-4_1 | G22: 1.4449 | H22: 1.4863 | J22: =H22-G22 -> 0.0414 | K22: =AVERAGE(J22:J26) -> 0.03694 | L22: =SUM(J22) -> 0.0414 | M22: =SUM(J26) -> 0.029
A23: 6 | B23: PLA | C23: 20 | D23: Våt | E23: 46090 | F23: A-1-4_2 | G23: 1.4469 | H23: 1.4843 | J23: =H23-G23 -> 0.0374
A24: 6 | B24: PLA | C24: 20 | D24: Våt | E24: 46090 | F24: A-1-4_3 | G24: 1.4467 | H24: 1.486 | J24: =H24-G24 -> 0.0393
A25: 6 | B25: PLA | C25: 20 | D25: Våt | E25: 46090 | F25: A-1-4_4 | G25: 1.4462 | H25: 1.4838 | J25: =H25-G25 -> 0.0376
A26: 6 | B26: PLA | C26: 20 | D26: Våt | E26: 46090 | F26: A-1-4_5 | G26: 1.4453 | H26: 1.4743 | J26: =H26-G26 -> 0.029
A27: 9 | B27: PLA | C27: 20 | D27: Tørr | E27: 46111 | F27: A-1-5_1 | G27: 1.4436 | H27: 1.4863 | I27: 1.4482 | J27: =H27-G27 -> 0.0427 | K27: =AVERAGE(J27:J31) -> 0.04798 | L27: =SUM(J29) -> 0.0773 | M27: =SUM(J30) -> 0.0309 | N27: =SUM(I27-G27) -> 0.0046 | O27: =AVERAGE(N27:N31) -> 0.0056 | P27: 0.0063 | Q27: 0.0046
A28: 9 | B28: PLA | C28: 20 | D28: Tørr | E28: 46111 | F28: A-1-5_2 | G28: 1.441 | H28: 1.4772 | I28: 1.447 | J28: =H28-G28 -> 0.0362 | N28: =SUM(I28-G28) -> 0.006
A29: 9 | B29: PLA | C29: 20 | D29: Tørr | E29: 46111 | F29: A-1-5_3 | G29: 1.444 | H29: 1.5213 | I29: 1.4491 | J29: =H29-G29 -> 0.0773 | N29: =SUM(I29-G29) -> 0.0051
A30: 9 | B30: PLA | C30: 20 | D30: Tørr | E30: 46111 | F30: A-1-5_4 | G30: 1.4415 | H30: 1.4724 | I30: 1.4478 | J30: =H30-G30 -> 0.0309 | N30: =SUM(I30-G30) -> 0.0063
A31: 9 | B31: PLA | C31: 20 | D31: Tørr | E31: 46111 | F31: A-1-5_5 | G31: 1.4425 | H31: 1.4953 | I31: 1.4485 | J31: =H31-G31 -> 0.0528 | N31: =SUM(I31-G31) -> 0.006
A32: 9 | B32: PLA | C32: 20 | D32: Våt | E32: 46111 | F32: A-1-6_1 | G32: 1.449 | H32: 1.4992 | J32: =H32-G32 -> 0.0502 | K32: =AVERAGE(J32:J36) -> 0.0447 | L32: =SUM(J36) -> 0.0595 | M32: =SUM(J35) -> 0.036
A33: 9 | B33: PLA | C33: 20 | D33: Våt | E33: 46111 | F33: A-1-6_2 | G33: 1.4432 | H33: 1.4816 | J33: =H33-G33 -> 0.0384
A34: 9 | B34: PLA | C34: 20 | D34: Våt | E34: 46111 | F34: A-1-6_3 | G34: 1.4419 | H34: 1.4813 | J34: =H34-G34 -> 0.0394
A35: 9 | B35: PLA | C35: 20 | D35: Våt | E35: 46111 | F35: A-1-6_4 | G35: 1.4394 | H35: 1.4754 | J35: =H35-G35 -> 0.036
A36: 9 | B36: PLA | C36: 20 | D36: Våt | E36: 46111 | F36: A-1-6_5 | G36: 1.4455 | H36: 1.505 | J36: =H36-G36 -> 0.0595
A37: 12 | B37: PLA | C37: 20 | D37: Tørr | E37: 46133 | F37: A-1-7_1 | G37: 1.4457 | H37: 1.4985 | I37: 1.4542 | J37: =SUM(H37-G37) -> 0.0528 | K37: =AVERAGE(J37:J41) -> 0.05996 | L37: =SUM(J40) -> 0.063 | M37: =SUM(J37) -> 0.0528 | N37: =SUM(I37-G37) -> 0.0085 | O37: =AVERAGE(N37:N41) -> 0.0095 | P37: 0.0138 | Q37: 0.0078
A38: 12 | B38: PLA | C38: 20 | D38: Tørr | E38: 46133 | F38: A-1-7_2 | G38: 1.4458 | H38: 1.5066 | I38: 1.455 | J38: =SUM(H38-G38) -> 0.0608 | N38: =SUM(I38-G38) -> 0.0092
A39: 12 | B39: PLA | C39: 20 | D39: Tørr | E39: 46133 | F39: A-1-7_3 | G39: 1.4472 | H39: 1.5096 | I39: 1.455 | J39: =SUM(H39-G39) -> 0.0624 | N39: =SUM(I39-G39) -> 0.0078
A40: 12 | B40: PLA | C40: 20 | D40: Tørr | E40: 46133 | F40: A-1-7_4 | G40: 1.4431 | H40: 1.5061 | I40: 1.4569 | J40: =SUM(H40-G40) -> 0.063 | N40: =SUM(I40-G40) -> 0.0138
A41: 12 | B41: PLA | C41: 20 | D41: Tørr | E41: 46133 | F41: A-1-7_5 | G41: 1.4452 | H41: 1.506 | I41: 1.4534 | J41: =SUM(H41-G41) -> 0.0608 | N41: =SUM(I41-G41) -> 0.0082
A42: 12 | B42: PLA | C42: 20 | D42: Våt | E42: 46133 | F42: A-1-8_1 | G42: 1.446 | H42: 1.4964 | J42: =SUM(H42-G42) -> 0.0504 | K42: =AVERAGE(J42:J46) -> 0.0527 | L42: =SUM(J46) -> 0.0567 | M42: =SUM(J42) -> 0.0504
A43: 12 | B43: PLA | C43: 20 | D43: Våt | E43: 46133 | F43: A-1-8_2 | G43: 1.4426 | H43: 1.4937 | J43: =SUM(H43-G43) -> 0.0511
...

Sheet PLA - Mellomregning
A1: Tabeller for vektendring og permanent vektendring for PLA
A3: Dette vedlegget viser mellomregninger og beregnede verdier brukt som grunnlag for diagrammer og resultatpresentasjon i rapporten. Verdiene er beregnet fra rådata presentert i fanen «PLA – Resultatberegninger».
A7: DEL 1 - Vektendring
A9: Tabell 1. Gjennomsnittlig vektendring brukt i resultatpresentasjon og punktdiagram.
B11: 20°C | D11: 40°C | F11: 60°C
A12: Uke | B12: Tørr | C12: Våt | D12: Tørr | E12: Våt | F12: Tørr | G12: Våt
A13: 3 | B13: 0.02944 | C13: 0.03232 | D13: 0.03928 | E13: 0.0412 | F13: 0.0617 | G13: 0.05282
A14: 6 | B14: 0.03916 | C14: 0.03694 | D14: 0.05052 | E14: 0.05252 | F14: 0.06872 | G14: 0.0678
A15: 9 | B15: 0.048 | C15: 0.0447 | D15: 0.1012 | E15: 0.06688 | F15: =NA() -> #N/A | G15: =NA() -> #N/A
A16: 12 | B16: 0.05996 | C16: 0.0527 | D16: 0.06074 | E16: 0.06112 | F16: -0.05098 | G16: -0.04746
A18: Tabellen viser gjennomsnittlige verdier beregnet fra rådata presentert i fanen «PLA – Resultatberegninger».
A21: Tabell 2. Maksimums- og minimumsverdier brukt til feilfelt for vektendring.
B23: 20°C | F23: 40°C | J23: 60°C
B24: Tørr | D24: Våt | F24: Tørr | H24: Våt | J24: Tørr | L24: Våt
A25: Uke | B25: Maks | C25: Min | D25: Maks | E25: Min | F25: Maks | G25: Min | H25: Maks | I25: Min | J25: Maks | K25: Min | L25: Maks | M25: Min
A26: 3 | B26: 0.0365 | C26: 0.0233 | D26: 0.041 | E26: 0.0272 | F26: 0.0445 | G26: 0.0433 | H26: 0.0431 | I26: 0.0331 | J26: 0.0614 | K26: 0.0629 | L26: 0.0541 | M26: 0.042
A27: 6 | B27: 0.0408 | C27: 0.0365 | D27: 0.0414 | E27: 0.029 | F27: 0.0457 | G27: 0.0617 | H27: 0.0708 | I27: 0.0554 | J27: 0.0644 | K27: 0.0714 | L27: 0.0638 | M27: 0.0649
A28: 9 | B28: 0.0773 | C28: 0.0309 | D28: 0.0595 | E28: 0.036 | F28: 0.0452 | G28: 0.0894 | H28: 0.0643 | I28: 0.0535 | J28: =NA() -> #N/A | K28: =NA() -> #N/A | L28: =NA() -> #N/A | M28: =NA() -> #N/A
A29: 12 | B29: 0.063 | C29: 0.0528 | D29: 0.0567 | E29: 0.0504 | F29: 0.0617 | G29: 0.0594 | H29: 0.0661 | I29: 0.049 | J29: -0.0649 | K29: -0.0452 | L29: -0.046 | M29: -0.0465
A31: Tabellen viser maksimums- og minimumsverdier for vektendring ved ulike temperaturer og tilstander. Verdiene er hentet fra fanen «PLA – Resultatberegninger» og brukt som grunnlag for beregning av feilfelt i punktdiagrammet.
A35: Tabell 3. Beregnede feilverdier brukt til feilfelt for vektendring.
B37: 20°C | F37: 40°C | J37: 60°C
B38: Tørr | D38: Våt | F38: Tørr | H38: Våt | J38: Tørr | L38: Våt
A39: Uke | B39: Maks - gj.snitt | C39: Gj.snitt - min | D39: Maks - gj.snitt | E39: Gj.snitt - min | F39: Maks - gj.snitt | G39: Gj.snitt - min | H39: Maks - gj.snitt | I39: Gj.snitt - min | J39: Maks - gj.snitt | K39: Gj.snitt - min | L39: Maks - gj.snitt | M39: Gj.snitt - min
A40: 3 | B40: =SUM(B26-B13) -> 0.00706 | C40: =SUM(B13-C26) -> 0.00614 | D40: =SUM(D26-C13) -> 0.00868 | E40: =SUM(C13-E26) -> 0.00512 | F40: =SUM(F26-D13) -> 0.00522 | G40: =G26-D13 -> 0.00402 | H40: =SUM(H26-E13) -> 0.0019 | I40: =SUM(E13-I26) -> 0.0081 | J40: =F13-J26 -> 0.0003 | K40: =K26-F13 -> 0.0012 | L40: =SUM(L26-G13) -> 0.00128 | M40: =SUM(G13-M26) -> 0.01082
A41: 6 | B41: =SUM(B27-B14) -> 0.00164 | C41: =SUM(B14-C27) -> 0.00266 | D41: =SUM(D27-C14) -> 0.00446 | E41: =SUM(C14-E27) -> 0.00794 | F41: =D14-F27 -> 0.00482 | G41: =G27-D14 -> 0.01118 | H41: =SUM(H27-E14) -> 0.01828 | I41: =I27-E14 -> 0.00288 | J41: =F14-J27 -> 0.00432 | K41: =K27-F14 -> 0.00268 | L41: =G14-L27 -> 0.004 | M41: =SUM(G14-M27) -> 0.0029
A42: 9 | B42: =SUM(B28-B15) -> 0.0293 | C42: =SUM(B15-C28) -> 0.0171 | D42: =SUM(D28-C15) -> 0.0148 | E42: =SUM(C15-E28) -> 0.0087 | F42: =D15-F28 -> 0.056 | G42: =SUM(D15-G28) -> 0.0118 | H42: =E15-H28 -> 0.00258 | I42: =SUM(E15-I28) -> 0.01338 | J42: =SUM(J28-F15) -> #N/A | K42: =SUM(F15-K28) -> #N/A | L42: =SUM(L28-G15) -> #N/A | M42: =SUM(G15-M28) -> #N/A
A43: 12 | B43: =SUM(B29-B16) -> 0.00304 | C43: =SUM(B16-C29) -> 0.00716 | D43: =SUM(D29-C16) -> 0.004 | E43: =SUM(C16-E29) -> 0.0023 | F43: =SUM(F29-D16) -> 0.00096 | G43: =SUM(D16-G29) -> 0.00134 | H43: =SUM(H29-E16) -> 0.00498 | I43: =SUM(E16-I29) -> 0.01212 | J43: =F16-J29 -> 0.01392 | K43: =K29-F16 -> 0.00578 | L43: =SUM(L29-G16) -> 0.00146 | M43: =M29-G16 -> 0.00096
A45: Tabellen viser beregnede feilverdier brukt til feilfelt i punktdiagrammet. Verdiene er beregnet fra maksimums-, minimums- og gjennomsnittsverdier hentet fra fanen «PLA – Resultatberegninger».
A50: DEL 2 - Permanent vektendring
A52: Tabell 4. Gjennomsnittlig permanent vektendring brukt i resultatpresentasjon og stolpediagram.
B54: 20°C | C54: 40°C | D54: 60°C
A55: Uke | B55: Tørr | C55: Tørr | D55: Tørr
A56: 3 | B56: 0.00476 | C56: 0.0088 | D56: 0.0136
A57: 6 | B57: 0.006 | C57: 0.007 | D57: -0.1084
A58: 9 | B58: 0.0056 | C58: 0.0085 | D58: =NA() -> #N/A
A59: 12 | B59: 0.0095 | C59: 0.0095 | D59: -0.2904
A61: Tabellen viser gjennomsnittlige verdier beregnet fra rådata presentert i fanen «PLA – Resultatberegninger».
A65: Tabell 5. Maksimums- og minimumsverdier brukt til feilfelt for permanent vektendring etter 48 timers tørking
B67: 20°C | D67: 40°C | F67: 60°C
...

Sheet PLA-Diagram
A1: Resultater for PLA – vektendring og permanent endring
A2: Dette vedlegget viser beregnede gjennomsnittsverdier og feilverdier brukt i resultatpresentasjonen for PLA-prøvene.
A3: Verdiene er beregnet fra rådata presentert i fanen «PLA – Resultatberegninger».
A5: Resultater for PLA – vektendring
A7: Tabell 1. Gjennomsnittlig vektendring brukt i resultatpresentasjon og punktdiagram.
A9: Verdier fra tabell 1. Gjennomsnittlig vektendring over tid
A10: Uke | B10: 20°C Tørr | C10: 20°C Våt | D10: 40°C Tørr | E10: 40°C Våt | F10: 60°C Tørr | G10: 60°C Våt
A11: 3 | B11: 0.02944 | C11: 0.03232 | D11: 0.03928 | E11: 0.0412 | F11: 0.0617 | G11: 0.05282
A12: 6 | B12: 0.03916 | C12: 0.03694 | D12: 0.05052 | E12: 0.05252 | F12: 0.06872 | G12: 0.0678
A13: 9 | B13: 0.048 | C13: 0.0447 | D13: 0.1012 | E13: 0.06688 | F13: =NA() -> #N/A | G13: =NA() -> #N/A
A14: 12 | B14: 0.05996 | C14: 0.0527 | D14: 0.06074 | E14: 0.06112 | F14: -0.05098 | G14: -0.04746
A17: Verdier fra tabell 3. Beregnede feilverdier brukt til feilfelt for vektendring.
B18: 20°C | F18: 40°C | J18: 60°C
B19: Tørr | D19: Våt | F19: Tørr | H19: Våt | J19: Tørr | L19: Våt
A20: Uke | B20: Maks - gj.snitt | C20: Gj.snitt - min | D20: Maks - gj.snitt | E20: Gj.snitt - min | F20: Maks - gj.snitt | G20: Gj.snitt - min | H20: Maks - gj.snitt | I20: Gj.snitt - min | J20: Maks - gj.snitt | K20: Gj.snitt - min | L20: Maks - gj.snitt | M20: Gj.snitt - min
A21: 3 | B21: 0.00706 | C21: 0.00614 | D21: 0.00868 | E21: 0.00512 | F21: 0.00522 | G21: 0.00402 | H21: 0.0019 | I21: 0.0081 | J21: 0.0003 | K21: 0.0012 | L21: 0.00128 | M21: 0.01082
A22: 6 | B22: 0.00164 | C22: 0.00266 | D22: 0.00446 | E22: 0.00794 | F22: 0.00482 | G22: 0.01118 | H22: 0.01828 | I22: 0.00288 | J22: 0.00432 | K22: 0.00268 | L22: 0.004 | M22: 0.0029
A23: 9 | B23: 0.0293 | C23: 0.0171 | D23: 0.0148 | E23: 0.0087 | F23: 0.056 | G23: 0.0118 | H23: 0.00258 | I23: 0.01338 | J23: #N/A | K23: #N/A | L23: #N/A | M23: #N/A
A24: 12 | B24: 0.00304 | C24: 0.00716 | D24: 0.004 | E24: 0.0023 | F24: 0.00096 | G24: 0.00134 | H24: 0.00498 | I24: 0.01212 | J24: 0.01392 | K24: 0.00578 | L24: 0.00146 | M24: 0.00096
A56: Resultater for PLA – permanent endring
A59: Verdier hentet fra tabell 4. Gjennomsnittlig permanent vektendring
A60: Uke | B60: 20°C Tørr | C60: 40°C Tørr | D60: 60°C Tørr
A61: 3 | B61: 0.00476 | C61: 0.0088 | D61: 0.0136
A62: 6 | B62: 0.006 | C62: 0.007 | D62: -0.1084
A63: 9 | B63: 0.0056 | C63: 0.0085 | D63: =NA() -> #N/A
A64: 12 | B64: 0.0095 | C64: 0.0095 | D64: -0.2904
A68: Verdier hentet fra tabell 6. Beregnede feilverdier brukt til feilfelt for permanent vektendring.
A69: Uke | B69: 20°C | D69: 40°C | F69: 60°C
B70: Maks - gj.snitt | C70: Gj.snitt - min | D70: Maks - gj.snitt | E70: Gj.snitt - min | F70: Maks - gj.snitt | G70: Gj.snitt - min
A71: 3 | B71: 0.00304 | C71: 0.00196 | D71: 0.0034 | E71: 0.0019 | F71: 0.0037 | G71: 0.0039
A72: 6 | B72: 0.0013 | C72: 0.0018 | D72: 0.0032 | E72: 0.0024 | F72: 0.021 | G72: 0.0217
A73: 9 | B73: 0.0007 | C73: 0.001 | D73: 0.003 | E73: 0.0041 | F73: #N/A | G73: #N/A
A74: 12 | B74: 0.0043 | C74: 0.0017 | D74: 0.0016 | E74: 0.0007 | F74: 0.0152 | G74: 0

Sheet PLA - Prosent
A1: PLA – prosentberegninger
A3: Andel av vektopptaket som ble værende i materialet etter tørking
A5: Uke | B5: Temperatur | C5: Gj.snittlig vektendring (g) | D5: Gj.snittlig permanent endring (g) | E5: Permanent andel av opptak (%)
A7: 3 | B7: 20°C | C7: 0.0294 | D7: 0.0048 | E7: =D7/C7 -> 0.16326531
A8: 6 | B8: 20°C | C8: 0.0392 | D8: 0.006 | E8: =D8/C8 -> 0.15306122
A9: 9 | B9: 20°C | C9: 0.048 | D9: 0.0056 | E9: =D9/C9 -> 0.11666667
A10: 12 | B10: 20°C | C10: 0.06 | D10: 0.0095 | E10: =D10/C10 -> 0.15833333
A11: 3 | B11: 40°C | C11: 0.0393 | D11: 0.0088 | E11: =D11/C11 -> 0.22391858
A12: 6 | B12: 40°C | C12: 0.0505 | D12: 0.007 | E12: =D12/C12 -> 0.13861386
A13: 9 | B13: 40°C | C13: 0.1012 | D13: 0.0085 | E13: =D13/C13 -> 0.083992095
A14: 12 | B14: 40°C | C14: 0.0607 | D14: 0.0095 | E14: =D14/C14 -> 0.15650741
A15: 3 | B15: 60°C | C15: 0.0617 | D15: 0.0136 | E15: =D15/C15 -> 0.22042139
A16: 6 | B16: 60°C | C16: 0.0687 | D16: -0.1084 | E16: =D16/C16 -> -1.5778748
A17: 9 | B17: 60°C | C17: =NA() -> #N/A | D17: =NA() -> #N/A | E17: =D17/C17 -> #N/A
A18: 12 | B18: 60°C | C18: -0.051 | D18: -0.2799 | E18: =D18/C18 -> 5.4882353
A21: Uke | B21: 20°C | C21: 40°C | D21: 60°C
A22: 3 | B22: 0.16326531 | C22: 0.22391858 | D22: 0.22042139
A23: 6 | B23: 0.15306122 | C23: 0.13861386 | D23: -1.5778748
A24: 9 | B24: 0.11666667 | C24: 0.083992095 | D24: #N/A
A25: 12 | B25: 0.15833333 | C25: 0.15650741 | D25: ikke representavit

Sheet PETG - Vektregistrering
D2: Plasttype: PETG | H2: Første testpinne i hvert sett skal ikke skylles
B4: Dato | D4: 28/1
B6: Prøve ID | C6: Startvekt | D6: Prøve ID | E6: Startvekt
B7: B-0-1 | C7: 1.4574 | D7: B-0-2 | E7: 1.4526
B8: B-0-1 | C8: 1.4593 | D8: B-0-2 | E8: 1.4498
B9: B-0-1 | C9: 1.4584 | D9: B-0-2 | E9: 1.4578
B10: B-0-1 | C10: 1.46 | D10: B-0-2 | E10: 1.4636
B11: B-0-1 | C11: 1.4566 | D11: B-0-2 | E11: 1.4556
B13: Temp 20C | L13: Temp 40C | V13: Temp 60C
B14: Tørr | G14: Våt | L14: Tørr | Q14: Våt | V14: tørr | AA14: våt
B15: Dato | C15: 27/1 | D15: 17/2 | E15: 46072 | G15: Dato | H15: 27/1 | I15: 17/2 | L15: Dato | M15: 27/1 | N15: 17/2 | O15: 46072 | Q15: Dato | R15: 27/1 | S15: 17/2 | V15: Dato | W15: 27/1 | X15: 17/2 | Y15: 46072 | AA15: Dato | AB15: 27/1 | AC15: 17/2
B17: Prøve ID | C17: Startvekt | D17: Sluttvekt | E17: Tørrvekt | G17: Prøve ID | H17: Startvekt | I17: Sluttvekt | L17: Prøve ID | M17: Startvekt | N17: Sluttvekt | O17: Tørrvekt | Q17: Prøve ID | R17: Startvekt | S17: Sluttvekt | V17: Prøve ID | W17: Startvekt | X17: Sluttvekt | Y17: Tørrvekt | AA17: Prøve ID | AB17: Startvekt | AC17: Sluttvekt
A18: ikke skylt | B18: B-1-1 | C18: 1.4611 | D18: 1.4854 | E18: 1.4705 | F18: ikke skylt | G18: B-1-2 | H18: 1.4594 | I18: 1.4796 | K18: ikke skylt | L18: B-2-1 | M18: 1.4584 | N18: 1.4886 | O18: 1.4682 | P18: ikke skylt | Q18: B-2-2 | R18: 1.4626 | S18: 1.4929 | U18: ikke skylt | V18: B-3-1 | W18: 1.45 | X18: 1.4883 | Y18: 1.4669 | Z18: ikke skylt | AA18: B-3-2 | AB18: 1.4559 | AC18: 1.4955
A19: skylt og tørket | B19: B-1-1 | C19: 1.4515 | D19: 1.4716 | E19: 1.4564 | F19: skylt og tørket | G19: B-1-2 | H19: 1.4527 | I19: 1.4748 | K19: skylt og tørket | L19: B-2-1 | M19: 1.4651 | N19: 1.494 | O19: 1.4662 | P19: skylt og tørket | Q19: B-2-2 | R19: 1.4608 | S19: 1.4925 | U19: skylt og tørket | V19: B-3-1 | W19: 1.4511 | X19: 1.4895 | Y19: 1.4641 | Z19: skylt og tørket | AA19: B-3-2 | AB19: 1.4647 | AC19: 1.509
A20: skylt og tørket | B20: B-1-1 | C20: 1.4578 | D20: 1.4827 | E20: 1.4665 | F20: skylt og tørket | G20: B-1-2 | H20: 1.4586 | I20: 1.4815 | K20: skylt og tørket | L20: B-2-1 | M20: 1.451 | N20: 1.4811 | O20: 1.4594 | P20: skylt og tørket | Q20: B-2-2 | R20: 1.4579 | S20: 1.486 | U20: skylt og tørket | V20: B-3-1 | W20: 1.4518 | X20: 1.4866 | Y20: 1.4632 | Z20: skylt og tørket | AA20: B-3-2 | AB20: 1.4614 | AC20: 1.503
A21: skylt og tørket | B21: B-1-1 | C21: 1.4668 | D21: 1.4989 | E21: 1.4751 | F21: skylt og tørket | G21: B-1-2 | H21: 1.4472 | I21: 1.4704 | K21: skylt og tørket | L21: B-2-1 | M21: 1.4514 | N21: 1.4802 | O21: 1.4594 | P21: skylt og tørket | Q21: B-2-2 | R21: 1.4576 | S21: 1.4906 | U21: skylt og tørket | V21: B-3-1 | W21: 1.4642 | X21: 1.5036 | Y21: 1.4794 | Z21: skylt og tørket | AA21: B-3-2 | AB21: 1.4578 | AC21: 1.5073
A22: skylt og tørket | B22: B-1-1 | C22: 1.4536 | D22: 1.4725 | E22: 1.4591 | F22: skylt og tørket | G22: B-1-2 | H22: 1.4656 | I22: 1.4912 | K22: skylt og tørket | L22: B-2-1 | M22: 1.4487 | N22: 1.4772 | O22: 1.4575 | P22: skylt og tørket | Q22: B-2-2 | R22: 1.446 | S22: 1.4729 | U22: skylt og tørket | V22: B-3-1 | W22: 1.4555 | X22: 1.4947 | Y22: 1.47 | Z22: skylt og tørket | AA22: B-3-2 | AB22: 1.444 | AC22: 1.4872
B25: Dato | C25: 27/1 | D25: 46090 | E25: 46092 | G25: Dato | H25: 27/1 | I25: 46090 | L25: Dato | M25: 27/1 | N25: 46090 | O25: 46092 | Q25: Dato | R25: 27/1 | S25: 46090 | V25: Dato | W25: 27/1 | X25: 46090 | Y25: 46092 | AA25: Dato | AB25: 27/1 | AC25: 46090
B27: Prøve ID | C27: Startvekt | D27: Sluttvekt | E27: Tørrvekt | G27: Prøve ID | H27: Startvekt | I27: Sluttvekt | L27: Prøve ID | M27: Startvekt | N27: Sluttvekt | O27: Tørrvekt | Q27: Prøve ID | R27: Startvekt | S27: Sluttvekt | V27: Prøve ID | W27: Startvekt | X27: Sluttvekt | Y27: Tørrvekt | AA27: Prøve ID | AB27: Startvekt | AC27: Sluttvekt
A28: ikke skylt | B28: B-1-3 | C28: 1.4589 | D28: 1.4876 | E28: 1.4661 | F28: ikke skylt | G28: B-1-4 | H28: 1.4659 | I28: 1.4866 | K28: ikke skylt | L28: B-2-3 | M28: 1.4556 | N28: 1.488 | O28: 1.4681 | P28: ikke skylt | Q28: B-2-4 | R28: 1.4452 | S28: 1.4751 | U28: ikke skylt | V28: B-3-3 | W28: 1.4548 | X28: 1.4977 | Y28: 1.4663 | Z28: ikke skylt | AA28: B-3-4 | AB28: 1.4643 | AC28: 1.5089
A29: skylt og tørket | B29: B-1-3 | C29: 1.4538 | D29: 1.4759 | E29: 1.4539 | F29: skylt og tørket | G29: B-1-4 | H29: 1.4647 | I29: 1.4864 | K29: skylt og tørket | L29: B-2-3 | M29: 1.4556 | N29: 1.4906 | O29: 1.4688 | P29: skylt og tørket | Q29: B-2-4 | R29: 1.4632 | S29: 1.4952 | U29: skylt og tørket | V29: B-3-3 | W29: 1.4657 | X29: 1.5111 | Y29: 1.4718 | Z29: skylt og tørket | AA29: B-3-4 | AB29: 1.461 | AC29: 1.5035
A30: skylt og tørket | B30: B-1-3 | C30: 1.45 | D30: 1.4741 | E30: 1.4639 | F30: skylt og tørket | G30: B-1-4 | H30: 1.4596 | I30: 1.4812 | K30: skylt og tørket | L30: B-2-3 | M30: 1.4565 | N30: 1.4872 | O30: 1.4645 | P30: skylt og tørket | Q30: B-2-4 | R30: 1.4603 | S30: 1.4927 | U30: skylt og tørket | V30: B-3-3 | W30: 1.4547 | X30: 1.5019 | Y30: 1.4706 | Z30: skylt og tørket | AA30: B-3-4 | AB30: 1.4514 | AC30: 1.4937
A31: skylt og tørket | B31: B-1-3 | C31: 1.463 | D31: 1.4903 | E31: 1.471 | F31: skylt og tørket | G31: B-1-4 | H31: 1.4566 | I31: 1.4808 | K31: skylt og tørket | L31: B-2-3 | M31: 1.4546 | N31: 1.4805 | O31: 1.4632 | P31: skylt og tørket | Q31: B-2-4 | R31: 1.4536 | S31: 1.4851 | U31: skylt og tørket | V31: B-3-3 | W31: 1.4618 | X31: 1.4995 | Y31: 1.4686 | Z31: skylt og tørket | AA31: B-3-4 | AB31: 1.4628 | AC31: 1.5038
A32: skylt og tørket | B32: B-1-3 | C32: 1.4544 | D32: 1.4774 | E32: 1.4622 | F32: skylt og tørket | G32: B-1-4 | H32: 1.4485 | I32: 1.4686 | K32: skylt og tørket | L32: B-2-3 | M32: 1.4581 | N32: 1.491 | O32: 1.4603 | P32: skylt og tørket | Q32: B-2-4 | R32: 1.4564 | S32: 1.4815 | U32: skylt og tørket | V32: B-3-3 | W32: 1.4604 | X32: 1.5017 | Y32: 1.4689 | Z32: skylt og tørket | AA32: B-3-4 | AB32: 1.4622 | AC32: 1.505
B35: Dato | C35: 27/1 | D35: 46111 | E35: 46113 | G35: Dato | H35: 27/1 | I35: 46111 | L35: Dato | M35: 27/1 | N35: 46111 | O35: 46113 | Q35: Dato | R35: 27/1 | S35: 46111 | V35: Dato | W35: 27/1 | X35: 46111 | Y35: 46113 | AA35: Dato | AB35: 27/1 | AC35: 46111
B37: Prøve ID | C37: Startvekt | D37: Sluttvekt | E37: Tørrvekt | G37: Prøve ID | H37: Startvekt | I37: Sluttvekt | L37: Prøve ID | M37: Startvekt | N37: Sluttvekt | O37: Tørrvekt | Q37: Prøve ID | R37: Startvekt | S37: Sluttvekt | V37: Prøve ID | W37: Startvekt | X37: Sluttvekt | Y37: Tørrvekt | AA37: Prøve ID | AB37: Startvekt | AC37: Sluttvekt
A38: ikke skylt | B38: B-1-5 | C38: 1.4488 | D38: 1.4752 | E38: 1.4642 | F38: ikke skylt | G38: B-1-6 | H38: 1.4584 | I38: 1.4907 | K38: ikke skylt | L38: B-2-5 | M38: 1.4575 | N38: 1.5552 | O38: 1.4681 | P38: ikke skylt | Q38: B-2-6 | R38: 1.4533 | S38: 1.4891 | U38: ikke skylt | V38: B-3-5 | W38: 1.4546 | X38: 1.4991 | Y38: 1.4658 | Z38: ikke skylt | AA38: B-3-6 | AB38: 1.4574 | AC38: 1.5095
A39: skylt og tørket | B39: B-1-5 | C39: 1.4518 | D39: 1.4827 | E39: 1.4561 | F39: skylt og tørket | G39: B-1-6 | H39: 1.4552 | I39: 1.5062 | K39: skylt og tørket | L39: B-2-5 | M39: 1.4601 | N39: 1.5593 | O39: 1.47 | P39: skylt og tørket | Q39: B-2-6 | R39: 1.4529 | S39: 1.4852 | U39: skylt og tørket | V39: B-3-5 | W39: 1.4477 | X39: 1.4894 | Y39: 1.4738 | Z39: skylt og tørket | AA39: B-3-6 | AB39: 1.4611 | AC39: 1.5082
A40: skylt og tørket | B40: B-1-5 | C40: 1.4549 | D40: 1.5044 | E40: 1.4646 | F40: skylt og tørket | G40: B-1-6 | H40: 1.4591 | I40: 1.4863 | K40: skylt og tørket | L40: B-2-5 | M40: 1.4642 | N40: 1.4966 | O40: 1.4669 | P40: skylt og tørket | Q40: B-2-6 | R40: 1.4579 | S40: 1.4901 | U40: skylt og tørket | V40: B-3-5 | W40: 1.4645 | X40: 1.5076 | Y40: 1.4707 | Z40: skylt og tørket | AA40: B-3-6 | AB40: 1.4509 | AC40: 1.5194
A41: skylt og tørket | B41: B-1-5 | C41: 1.4486 | D41: 1.4761 | E41: 1.473 | F41: skylt og tørket | G41: B-1-6 | H41: 1.4543 | I41: 1.4801 | K41: skylt og tørket | L41: B-2-5 | M41: 1.4468 | N41: 1.4744 | O41: 1.4634 | P41: skylt og tørket | Q41: B-2-6 | R41: 1.4568 | S41: 1.5372 | U41: skylt og tørket | V41: B-3-5 | W41: 1.449 | X41: 1.5325 | Y41: 1.4687 | Z41: skylt og tørket | AA41: B-3-6 | AB41: 1.4607 | AC41: 1.5176
A42: skylt og tørket | B42: B-1-5 | C42: 1.464 | D42: 1.5193 | E42: 1.4611 | F42: skylt og tørket | G42: B-1-6 | H42: 1.4491 | I42: 1.4797 | K42: skylt og tørket | L42: B-2-5 | M42: 1.4556 | N42: 1.4823 | O42: 1.4609 | P42: skylt og tørket | Q42: B-2-6 | R42: 1.4566 | S42: 1.4953 | U42: skylt og tørket | V42: B-3-5 | W42: 1.4492 | X42: 1.4887 | Y42: 1.4683 | Z42: skylt og tørket | AA42: B-3-6 | AB42: 1.4648 | AC42: 1.5143
B45: Dato | C45: 27/1 | D45: 46133 | E45: 46135 | G45: Dato | H45: 46133 | L45: Dato | M45: 27/1 | N45: 46133 | O45: 46135 | Q45: Dato | R45: 27/1 | S45: 46133 | V45: Dato | W45: 27/1 | X45: 46133 | Y45: 46135 | AA45: Dato | AB45: 27/1 | AC45: 46133
B47: Prøve ID | C47: Startvekt | D47: Sluttvekt | E47: Tørrvekt | G47: Prøve ID | H47: Startvekt | I47: Sluttvekt | L47: Prøve ID | M47: Startvekt | N47: Sluttvekt | O47: Tørrvekt | Q47: Prøve ID | R47: Startvekt | S47: Sluttvekt | V47: Prøve ID | W47: Startvekt | X47: Sluttvekt | Y47: Tørrvekt | AA47: Prøve ID | AB47: Startvekt | AC47: Sluttvekt
A48: ikke skylt | B48: B-1-7 | C48: 1.4556 | D48: 1.4914 | E48: 1.4623 | F48: ikke skylt | G48: B-1-8 | H48: 1.4523 | I48: 1.4872 | K48: ikke skylt | L48: B-2-7 | M48: 1.4566 | N48: 1.5049 | O48: 1.468 | P48: ikke skylt | Q48: B-2-8 | R48: 1.4592 | S48: 1.4949 | U48: ikke skylt | V48: B-3-7 | W48: 1.4523 | X48: 1.4982 | Y48: 1.4653 | Z48: ikke skylt | AA48: B-3-8 | AB48: 1.4584 | AC48: 1.5044
A49: skylt og tørket | B49: B-1-7 | C49: 1.4453 | D49: 1.4741 | E49: 1.4502 | F49: skylt og tørket | G49: B-1-8 | H49: 1.4644 | I49: 1.5084 | K49: skylt og tørket | L49: B-2-7 | M49: 1.4612 | N49: 1.5068 | O49: 1.4715 | P49: skylt og tørket | Q49: B-2-8 | R49: 1.4531 | S49: 1.5151 | U49: skylt og tørket | V49: B-3-7 | W49: 1.4637 | X49: 1.5209 | Y49: 1.4776 | Z49: skylt og tørket | AA49: B-3-8 | AB49: 1.45 | AC49: 1.504
A50: skylt og tørket | B50: B-1-7 | C50: 1.4536 | D50: 1.4938 | E50: 1.4613 | F50: skylt og tørket | G50: B-1-8 | H50: 1.4537 | I50: 1.494 | K50: skylt og tørket | L50: B-2-7 | M50: 1.459 | N50: 1.5066 | O50: 1.4703 | P50: skylt og tørket | Q50: B-2-8 | R50: 1.4515 | S50: 1.4994 | U50: skylt og tørket | V50: B-3-7 | W50: 1.4671 | X50: 1.5174 | Y50: 1.4781 | Z50: skylt og tørket | AA50: B-3-8 | AB50: 1.46 | AC50: 1.5072
A51: skylt og tørket | B51: B-1-7 | C51: 1.4634 | D51: 1.5069 | E51: 1.4687 | F51: skylt og tørket | G51: B-1-8 | H51: 1.4467 | I51: 1.4879 | K51: skylt og tørket | L51: B-2-7 | M51: 1.4557 | N51: 1.5017 | O51: 1.4671 | P51: skylt og tørket | Q51: B-2-8 | R51: 1.4621 | S51: 1.5081 | U51: skylt og tørket | V51: B-3-7 | W51: 1.4459 | X51: 1.5004 | Y51: 1.4579 | Z51: skylt og tørket | AA51: B-3-8 | AB51: 1.4562 | AC51: 1.5076
A52: skylt og tørket | B52: B-1-7 | C52: 1.4603 | D52: 1.4969 | E52: 1.4653 | F52: skylt og tørket | G52: B-1-8 | H52: 1.4509 | I52: 1.4866 | K52: skylt og tørket | L52: B-2-7 | M52: 1.4525 | N52: 1.5016 | O52: 1.4629 | P52: skylt og tørket | Q52: B-2-8 | R52: 1.4651 | S52: 1.5095 | U52: skylt og tørket | V52: B-3-7 | W52: 1.4531 | X52: 1.4982 | Y52: 1.4667 | Z52: skylt og tørket | AA52: B-3-8 | AB52: 1.4533 | AC52: 1.5097

Sheet PETG - Resultatberegninger
A1: Gjennomsnittlige verdier brukt i resultatpresentasjonen for PETG
A4: Uke | B4: Type plast | C4: Temperatur | D4: Tilstand | E4: Dato | F4: Prøve ID | G4: Startvekt | H4: Sluttvekt | I4: Tørket etter 48 timer | J4: Vektendring | K4: Gj.snittlig vektendring | L4: Max vektendring | M4: Min vektendring | N4: Permanent endring | O4: Gj.snittlig premanent endring | P4: Max permanent | Q4: Min permanent
A5: 20 °C
A6: 3 | B6: PETG | C6: 20 | D6: Tørr | E6: 46070 | F6: B-1-1_1 | G6: 1.4611 | H6: 1.4854 | I6: 1.4705 | J6: =SUM(H6-G6) -> 0.0243 | K6: =AVERAGE(J6:J10) -> 0.02406 | L6: =SUM(J9) -> 0.0321 | M6: =SUM(J10) -> 0.0189 | N6: =SUM(I6-G6) -> 0.0094 | O6: =AVERAGE(N6:N10) -> 0.00736 | P6: =SUM(N6) -> 0.0094 | Q6: =SUM(N7) -> 0.0049
A7: 3 | B7: PETG | C7: 20 | D7: Tørr | E7: 46070 | F7: B-1-1_2 | G7: 1.4515 | H7: 1.4716 | I7: 1.4564 | J7: =SUM(H7-G7) -> 0.0201 | N7: =SUM(I7-G7) -> 0.0049
A8: 3 | B8: PETG | C8: 20 | D8: Tørr | E8: 46070 | F8: B-1-1_3 | G8: 1.4578 | H8: 1.4827 | I8: 1.4665 | J8: =SUM(H8-G8) -> 0.0249 | N8: =SUM(I8-G8) -> 0.0087
A9: 3 | B9: PETG | C9: 20 | D9: Tørr | E9: 46070 | F9: B-1-1_4 | G9: 1.4668 | H9: 1.4989 | I9: 1.4751 | J9: =SUM(H9-G9) -> 0.0321 | N9: =SUM(I9-G9) -> 0.0083
A10: 3 | B10: PETG | C10: 20 | D10: Tørr | E10: 46070 | F10: B-1-1_5 | G10: 1.4536 | H10: 1.4725 | I10: 1.4591 | J10: =SUM(H10-G10) -> 0.0189 | N10: =SUM(I10-G10) -> 0.0055
A11: 3 | B11: PETG | C11: 20 | D11: Våt | E11: 46070 | F11: B-1-2_1 | G11: 1.4594 | H11: 1.4796 | J11: =SUM(H11-G11) -> 0.0202 | K11: =AVERAGE(J11:J15) -> 0.0228 | L11: =SUM(J15) -> 0.0256 | M11: =SUM(J11) -> 0.0202
A12: 3 | B12: PETG | C12: 20 | D12: Våt | E12: 46070 | F12: B-1-2_2 | G12: 1.4527 | H12: 1.4748 | J12: =SUM(H12-G12) -> 0.0221
A13: 3 | B13: PETG | C13: 20 | D13: Våt | E13: 46070 | F13: B-1-2_3 | G13: 1.4586 | H13: 1.4815 | J13: =SUM(H13-G13) -> 0.0229
A14: 3 | B14: PETG | C14: 20 | D14: Våt | E14: 46070 | F14: B-1-2_4 | G14: 1.4472 | H14: 1.4704 | J14: =SUM(H14-G14) -> 0.0232
A15: 3 | B15: PETG | C15: 20 | D15: Våt | E15: 46070 | F15: B-1-2_5 | G15: 1.4656 | H15: 1.4912 | J15: =SUM(H15-G15) -> 0.0256
A16: 6 | B16: PETG | C16: 20 | D16: Tørr | E16: 46090 | F16: B-1-3_1 | G16: 1.4589 | H16: 1.4876 | I16: 1.4661 | J16: =H16-G16 -> 0.0287 | K16: =AVERAGE(J16:J20) -> 0.02504 | L16: =SUM(J16) -> 0.0287 | M16: =SUM(J17) -> 0.0221 | N16: =SUM(I16-G16) -> 0.0072 | O16: =AVERAGE(N16:N20) -> 0.0074 | P16: =SUM(N18) -> 0.0139 | Q16: =SUM(N17) -> 0.0001
A17: 6 | B17: PETG | C17: 20 | D17: Tørr | E17: 46090 | F17: B-1-3_2 | G17: 1.4538 | H17: 1.4759 | I17: 1.4539 | J17: =H17-G17 -> 0.0221 | N17: =SUM(I17-G17) -> 0.0001
A18: 6 | B18: PETG | C18: 20 | D18: Tørr | E18: 46090 | F18: B-1-3_3 | G18: 1.45 | H18: 1.4741 | I18: 1.4639 | J18: =H18-G18 -> 0.0241 | N18: =SUM(I18-G18) -> 0.0139
A19: 6 | B19: PETG | C19: 20 | D19: Tørr | E19: 46090 | F19: B-1-3_4 | G19: 1.463 | H19: 1.4903 | I19: 1.471 | J19: =H19-G19 -> 0.0273 | N19: =SUM(I19-G19) -> 0.008
A20: 6 | B20: PETG | C20: 20 | D20: Tørr | E20: 46090 | F20: B-1-3_5 | G20: 1.4544 | H20: 1.4774 | I20: 1.4622 | J20: =H20-G20 -> 0.023 | N20: =SUM(I20-G20) -> 0.0078
A21: 6 | B21: PETG | C21: 20 | D21: Våt | E21: 46090 | F21: B-1-4_1 | G21: 1.4659 | H21: 1.4866 | J21: =H21-G21 -> 0.0207 | K21: =AVERAGE(J21:J25) -> 0.02166 | L21: =SUM(J24) -> 0.0242 | M21: =SUM(J25) -> 0.0201
A22: 6 | B22: PETG | C22: 20 | D22: Våt | E22: 46090 | F22: B-1-4_2 | G22: 1.4647 | H22: 1.4864 | J22: =H22-G22 -> 0.0217
A23: 6 | B23: PETG | C23: 20 | D23: Våt | E23: 46090 | F23: B-1-4_3 | G23: 1.4596 | H23: 1.4812 | J23: =H23-G23 -> 0.0216
A24: 6 | B24: PETG | C24: 20 | D24: Våt | E24: 46090 | F24: B-1-4_4 | G24: 1.4566 | H24: 1.4808 | J24: =H24-G24 -> 0.0242
A25: 6 | B25: PETG | C25: 20 | D25: Våt | E25: 46090 | F25: B-1-4_5 | G25: 1.4485 | H25: 1.4686 | J25: =H25-G25 -> 0.0201
A26: 9 | B26: PETG | C26: 20 | D26: Tørr | E26: 46111 | F26: B-1-5_1 | G26: 1.4488 | H26: 1.4752 | I26: 1.4642 | J26: =H26-G26 -> 0.0264 | K26: =AVERAGE(J26) -> 0.0264 | L26: =SUM(J30) -> 0.0553 | M26: =SUM(J26) -> 0.0264 | N26: =SUM(I26-G26) -> 0.0154 | O26: =AVERAGE(N26:N30) -> 0.01018 | P26: =SUM(N29) -> 0.0244 | Q26: =SUM(N30) -> -0.0029
A27: 9 | B27: PETG | C27: 20 | D27: Tørr | E27: 46111 | F27: B-1-5_2 | G27: 1.4518 | H27: 1.4827 | I27: 1.4561 | J27: =H27-G27 -> 0.0309 | N27: =SUM(I27-G27) -> 0.0043
A28: 9 | B28: PETG | C28: 20 | D28: Tørr | E28: 46111 | F28: B-1-5_3 | G28: 1.4549 | H28: 1.5044 | I28: 1.4646 | J28: =H28-G28 -> 0.0495 | N28: =SUM(I28-G28) -> 0.0097
A29: 9 | B29: PETG | C29: 20 | D29: Tørr | E29: 46111 | F29: B-1-5_4 | G29: 1.4486 | H29: 1.4761 | I29: 1.473 | J29: =H29-G29 -> 0.0275 | N29: =SUM(I29-G29) -> 0.0244
A30: 9 | B30: PETG | C30: 20 | D30: Tørr | E30: 46111 | F30: B-1-5_5 | G30: 1.464 | H30: 1.5193 | I30: 1.4611 | J30: =H30-G30 -> 0.0553 | N30: =SUM(I30-G30) -> -0.0029
A31: 9 | B31: PETG | C31: 20 | D31: Våt | E31: 46111 | F31: B-1-6_1 | G31: 1.4584 | H31: 1.4907 | J31: =H31-G31 -> 0.0323 | K31: =AVERAGE(J31:J35) -> 0.03338 | L31: =SUM(J32) -> 0.051 | M31: =SUM(J34) -> 0.0258
A32: 9 | B32: PETG | C32: 20 | D32: Våt | E32: 46111 | F32: B-1-6_2 | G32: 1.4552 | H32: 1.5062 | J32: =H32-G32 -> 0.051
A33: 9 | B33: PETG | C33: 20 | D33: Våt | E33: 46111 | F33: B-1-6_3 | G33: 1.4591 | H33: 1.4863 | J33: =H33-G33 -> 0.0272
A34: 9 | B34: PETG | C34: 20 | D34: Våt | E34: 46111 | F34: B-1-6_4 | G34: 1.4543 | H34: 1.4801 | J34: =H34-G34 -> 0.0258
A35: 9 | B35: PETG | C35: 20 | D35: Våt | E35: 46111 | F35: B-1-6_5 | G35: 1.4491 | H35: 1.4797 | J35: =H35-G35 -> 0.0306
A36: 12 | B36: PETG | C36: 20 | D36: Tørr | E36: 46133 | F36: B-1-7_1 | G36: 1.4556 | H36: 1.4914 | I36: 1.4623 | J36: =SUM(H36-G36) -> 0.0358 | K36: =AVERAGE(J36:J40) -> 0.03698 | L36: =SUM(J39) -> 0.0435 | M36: =SUM(J37) -> 0.0288 | N36: =SUM(I36-G36) -> 0.0067 | O36: =AVERAGE(N36:N40) -> 0.00592 | P36: =SUM(N38) -> 0.0077 | Q36: =SUM(N37) -> 0.0049
A37: 12 | B37: PETG | C37: 20 | D37: Tørr | E37: 46133 | F37: B-1-7_2 | G37: 1.4453 | H37: 1.4741 | I37: 1.4502 | J37: =SUM(H37-G37) -> 0.0288 | N37: =SUM(I37-G37) -> 0.0049
A38: 12 | B38: PETG | C38: 20 | D38: Tørr | E38: 46133 | F38: B-1-7_3 | G38: 1.4536 | H38: 1.4938 | I38: 1.4613 | J38: =SUM(H38-G38) -> 0.0402 | N38: =SUM(I38-G38) -> 0.0077
A39: 12 | B39: PETG | C39: 20 | D39: Tørr | E39: 46133 | F39: B-1-7_4 | G39: 1.4634 | H39: 1.5069 | I39: 1.4687 | J39: =SUM(H39-G39) -> 0.0435 | N39: =SUM(I39-G39) -> 0.0053
A40: 12 | B40: PETG | C40: 20 | D40: Tørr | E40: 46133 | F40: B-1-7_5 | G40: 1.4603 | H40: 1.4969 | I40: 1.4653 | J40: =SUM(H40-G40) -> 0.0366 | N40: =SUM(I40-G40) -> 0.005
A41: 12 | B41: PETG | C41: 20 | D41: Våt | E41: 46133 | F41: B-1-8_1 | G41: 1.4523 | H41: 1.4872 | J41: =SUM(H41-G41) -> 0.0349 | K41: =AVERAGE(J41:J45) -> 0.03922 | L41: =SUM(J42) -> 0.044 | M41: =SUM(J41) -> 0.0349
A42: 12 | B42: PETG | C42: 20 | D42: Våt | E42: 46133 | F42: B-1-8_2 | G42: 1.4644 | H42: 1.5084 | J42: =SUM(H42-G42) -> 0.044
...

Sheet PETG - Mellomregning
A1: Tabeller for vektendring og permanent vektendring for PETG
A3: Dette vedlegget viser mellomregninger og beregnede verdier brukt som grunnlag for diagrammer og resultatpresentasjon i rapporten. Verdiene er beregnet fra rådata presentert i fanen «PETG – Resultatberegninger».
A7: DEL 1 - Vektendring
A9: Tabell 1. Gjennomsnittlig vektendring brukt i resultatpresentasjon og punktdiagram.
B11: 20°C | D11: 40°C | F11: 60°C
A12: Uke | B12: Tørr | C12: Våt | D12: Tørr | E12: Våt | F12: Tørr | G12: Våt
A13: 3 | B13: =SUM('PETG - Resultatberegninger'!K6) -> 0.02406 | C13: =SUM('PETG - Resultatberegninger'!K11) -> 0.0228 | D13: =SUM('PETG - Resultatberegninger'!K47) -> 0.0293 | E13: =SUM('PETG - Resultatberegninger'!K52) -> 0.03 | F13: =SUM('PETG - Resultatberegninger'!K88) -> 0.03802 | G13: =SUM('PETG - Resultatberegninger'!K93) -> 0.04364
A14: 6 | B14: =SUM('PETG - Resultatberegninger'!K16) -> 0.02504 | C14: =SUM('PETG - Resultatberegninger'!K21) -> 0.02166 | D14: =SUM('PETG - Resultatberegninger'!K57) -> 0.03138 | E14: =SUM('PETG - Resultatberegninger'!K62) -> 0.03018 | F14: =SUM('PETG - Resultatberegninger'!K98) -> 0.0429 | G14: =SUM('PETG - Resultatberegninger'!K103) -> 0.04264
A15: 9 | B15: =SUM('PETG - Resultatberegninger'!K26) -> 0.0264 | C15: =SUM('PETG - Resultatberegninger'!K31) -> 0.03338 | D15: =SUM('PETG - Resultatberegninger'!K67) -> 0.05672 | E15: =SUM('PETG - Resultatberegninger'!K72) -> 0.04388 | F15: =SUM('PETG - Resultatberegninger'!K108) -> 0.0445 | G15: =SUM('PETG - Resultatberegninger'!K113) -> 0.05482
A16: 12 | B16: =SUM('PETG - Resultatberegninger'!K36) -> 0.03698 | C16: =SUM('PETG - Resultatberegninger'!K41) -> 0.03922 | D16: =SUM('PETG - Resultatberegninger'!K77) -> 0.04732 | E16: =SUM('PETG - Resultatberegninger'!K82) -> 0.0472 | F16: =SUM('PETG - Resultatberegninger'!K118) -> 0.0506 | G16: =SUM('PETG - Resultatberegninger'!K123) -> 0.051
A18: Tabellen viser gjennomsnittlige verdier beregnet fra rådata presentert i fanen «PETG – Resultatberegninger».
A21: Tabell 2. Maksimums- og minimumsverdier brukt til feilfelt for vektendring.
B23: 20°C | F23: 40°C | J23: 60°C
B24: Tørr | D24: Våt | F24: Tørr | H24: Våt | J24: Tørr | L24: Våt
A25: Uke | B25: Maks | C25: Min | D25: Maks | E25: Min | F25: Maks | G25: Min | H25: Maks | I25: Min | J25: Maks | K25: Min | L25: Maks | M25: Min
A26: 3 | B26: 0.0321 | C26: 0.0189 | D26: 0.0256 | E26: 0.0202 | F26: 0.0302 | G26: 0.0285 | H26: 0.033 | I26: 0.0269 | J26: 0.0394 | K26: 0.0348 | L26: 0.0495 | M26: 0.0396
A27: 6 | B27: 0.0287 | C27: 0.0221 | D27: 0.0242 | E27: 0.0201 | F27: 0.035 | G27: 0.0259 | H27: 0.0324 | I27: 0.0251 | J27: 0.0472 | K27: 0.0377 | L27: 0.0446 | M27: 0.041
A28: 9 | B28: 0.0553 | C28: 0.0264 | D28: 0.051 | E28: 0.0258 | F28: 0.0992 | G28: 0.0267 | H28: 0.0804 | I28: 0.0322 | J28: 0.0835 | K28: 0.0395 | L28: 0.0685 | M28: 0.0471
A29: 12 | B29: 0.0435 | C29: 0.0288 | D29: 0.044 | E29: 0.0349 | F29: 0.0491 | G29: 0.0456 | H29: 0.062 | I29: 0.0357 | J29: 0.0572 | K29: 0.0451 | L29: 0.0564 | M29: 0.046
A31: Tabellen viser maksimums- og minimumsverdier for vektendring ved ulike temperaturer og tilstander. Verdiene er hentet fra fanen «PETG – Resultatberegninger» og brukt som grunnlag for beregning av feilfelt i punktdiagrammet.
A35: Tabell 3. Beregnede feilverdier brukt til feilfelt for vektendring.
B37: 20°C | F37: 40°C | J37: 60°C
B38: Tørr | D38: Våt | F38: Tørr | H38: Våt | J38: Tørr | L38: Våt
A39: Uke | B39: Maks - gj.snitt | C39: Gj.snitt - min | D39: Maks - gj.snitt | E39: Gj.snitt - min | F39: Maks - gj.snitt | G39: Gj.snitt - min | H39: Maks - gj.snitt | I39: Gj.snitt - min | J39: Maks - gj.snitt | K39: Gj.snitt - min | L39: Maks - gj.snitt | M39: Gj.snitt - min
A40: 3 | B40: =SUM(B26-B13) -> 0.00804 | C40: =SUM(B13-C26) -> 0.00516 | D40: =SUM(D26-C13) -> 0.0028 | E40: =SUM(C13-E26) -> 0.0026 | F40: =SUM(F26-D13) -> 0.0009 | G40: =SUM(D13-G26) -> 0.0008 | H40: =SUM(H26-E13) -> 0.003 | I40: =SUM(E13-I26) -> 0.0031 | J40: =SUM(J26-F13) -> 0.00138 | K40: =SUM(F13-K26) -> 0.00322 | L40: =SUM(L26-G13) -> 0.00586 | M40: =SUM(G13-M26) -> 0.00404
A41: 6 | B41: =SUM(B27-B14) -> 0.00366 | C41: =SUM(B14-C27) -> 0.00294 | D41: =SUM(D27-C14) -> 0.00254 | E41: =SUM(C14-E27) -> 0.00156 | F41: =SUM(F27-D14) -> 0.00362 | G41: =SUM(D14-G27) -> 0.00548 | H41: =SUM(H27-E14) -> 0.00222 | I41: =SUM(E14-I27) -> 0.00508 | J41: =SUM(J27-F14) -> 0.0043 | K41: =SUM(F14-K27) -> 0.0052 | L41: =SUM(L27-G14) -> 0.00196 | M41: =SUM(G14-M27) -> 0.00164
A42: 9 | B42: =SUM(B28-B15) -> 0.0289 | C42: =SUM(B15-C28) -> 0 | D42: =SUM(D28-C15) -> 0.01762 | E42: =SUM(C15-E28) -> 0.00758 | F42: =SUM(F28-D15) -> 0.04248 | G42: =SUM(D15-G28) -> 0.03002 | H42: =SUM(H28-E15) -> 0.03652 | I42: =SUM(E15-I28) -> 0.01168 | J42: =SUM(J28-F15) -> 0.039 | K42: =SUM(F15-K28) -> 0.005 | L42: =SUM(L28-G15) -> 0.01368 | M42: =SUM(G15-M28) -> 0.00772
A43: 12 | B43: =SUM(B29-B16) -> 0.00652 | C43: =SUM(B16-C29) -> 0.00818 | D43: =SUM(D29-C16) -> 0.00478 | E43: =SUM(C16-E29) -> 0.00432 | F43: =SUM(F29-D16) -> 0.00178 | G43: =SUM(D16-G29) -> 0.00172 | H43: =SUM(H29-E16) -> 0.0148 | I43: =SUM(E16-I29) -> 0.0115 | J43: =SUM(J29-F16) -> 0.0066 | K43: =SUM(F16-K29) -> 0.0055 | L43: =SUM(L29-G16) -> 0.0054 | M43: =SUM(G16-M29) -> 0.005
A45: Tabellen viser beregnede feilverdier brukt til feilfelt i punktdiagrammet. Verdiene er beregnet fra maksimums-, minimums- og gjennomsnittsverdier hentet fra fanen «PETG – Resultatberegninger».
A50: DEL 2 - Permanent vektendring
A52: Tabell 4. Gjennomsnittlig permanent vektendring brukt i resultatpresentasjon og stolpediagram.
B54: 20°C | C54: 40°C | D54: 60°C
A55: Uke | B55: Tørr | C55: Tørr | D55: Tørr
A56: 3 | B56: =SUM('PETG - Resultatberegninger'!O6) -> 0.00736 | C56: =SUM('PETG - Resultatberegninger'!O47) -> 0.00722 | D56: =SUM('PETG - Resultatberegninger'!O88) -> 0.0142
A57: 6 | B57: =SUM('PETG - Resultatberegninger'!O16) -> 0.0074 | C57: =SUM('PETG - Resultatberegninger'!O57) -> 0.0089 | D57: =SUM('PETG - Resultatberegninger'!O98) -> 0.00976
A58: 9 | B58: =SUM('PETG - Resultatberegninger'!O26) -> 0.01018 | C58: =SUM('PETG - Resultatberegninger'!O67) -> 0.00902 | D58: =SUM('PETG - Resultatberegninger'!O108) -> 0.01646
A59: 12 | B59: =SUM('PETG - Resultatberegninger'!O36) -> 0.00592 | C59: =SUM('PETG - Resultatberegninger'!O77) -> 0.01096 | D59: =SUM('PETG - Resultatberegninger'!O118) -> 0.0127
A61: Tabellen viser gjennomsnittlige verdier beregnet fra rådata presentert i fanen «PETG – Resultatberegninger».
A65: Tabell 5. Maksimums- og minimumsverdier brukt til feilfelt for permanent vektendring etter 48 timers tørking
B67: 20°C | D67: 40°C | F67: 60°C
...

Sheet PETG - Diagrammer
A1: Resultater for PETG – vektendring og permanent endring
A2: Dette vedlegget viser beregnede gjennomsnittsverdier og feilverdier brukt i resultatpresentasjonen for PETG-prøvene.
A3: Verdiene er beregnet fra rådata presentert i fanen «PETG – Resultatberegninger».
A5: Resultater for PETG – vektendring
A7: Tabell 1. Gjennomsnittlig vektendring brukt i resultatpresentasjon og punktdiagram.
A9: Verdier fra tabell 1. Gjennomsnittlig vektendring over tid
A10: Uke | B10: 20°C Tørr | C10: 20°C Våt | D10: 40°C Tørr | E10: 40°C Våt | F10: 60°C Tørr | G10: 60°C Våt
A11: 3 | B11: 0.0241 | C11: 0.0228 | D11: 0.0293 | E11: 0.03 | F11: 0.038 | G11: 0.0436
A12: 6 | B12: 0.025 | C12: 0.0217 | D12: 0.0314 | E12: 0.0302 | F12: 0.0429 | G12: 0.0426
A13: 9 | B13: 0.0264 | C13: 0.0334 | D13: 0.0567 | E13: 0.0439 | F13: 0.0445 | G13: 0.0548
A14: 12 | B14: 0.037 | C14: 0.0392 | D14: 0.0473 | E14: 0.0472 | F14: 0.0506 | G14: 0.051
A17: Verdier fra tabell 3. Beregnede feilverdier brukt til feilfelt for vektendring.
B18: 20°C | F18: 40°C | J18: 60°C
B19: Tørr | D19: Våt | F19: Tørr | H19: Våt | J19: Tørr | L19: Våt
A20: Uke | B20: Maks - gj.snitt | C20: Gj.snitt - min | D20: Maks - gj.snitt | E20: Gj.snitt - min | F20: Maks - gj.snitt | G20: Gj.snitt - min | H20: Maks - gj.snitt | I20: Gj.snitt - min | J20: Maks - gj.snitt | K20: Gj.snitt - min | L20: Maks - gj.snitt | M20: Gj.snitt - min
A21: 3 | B21: 0.00804 | C21: 0.00516 | D21: 0.0028 | E21: 0.0026 | F21: 0.0009 | G21: 0.0008 | H21: 0.003 | I21: 0.0031 | J21: 0.00138 | K21: 0.00322 | L21: 0.00586 | M21: 0.00404
A22: 6 | B22: 0.00366 | C22: 0.00294 | D22: 0.00254 | E22: 0.00156 | F22: 0.00362 | G22: 0.00548 | H22: 0.00222 | I22: 0.00508 | J22: 0.0043 | K22: 0.0052 | L22: 0.00196 | M22: 0.00164
A23: 9 | B23: 0.0289 | C23: 0 | D23: 0.01762 | E23: 0.00758 | F23: 0.04248 | G23: 0.03002 | H23: 0.03652 | I23: 0.01168 | J23: 0.039 | K23: 0.005 | L23: 0.01368 | M23: 0.00772
A24: 12 | B24: 0.00652 | C24: 0.00818 | D24: 0.00478 | E24: 0.00432 | F24: 0.00178 | G24: 0.00172 | H24: 0.0148 | I24: 0.0115 | J24: 0.0066 | K24: 0.0055 | L24: 0.0054 | M24: 0.005
A59: Resultater for PETG – permanent endring
A62: Gjennomsnittlig permanent vektendring
A63: Uke | B63: 20°C Tørr | C63: 40°C Tørr | D63: 60°C Tørr
A64: 3 | B64: 0.00736 | C64: 0.00722 | D64: 0.0142
A65: 6 | B65: 0.0074 | C65: 0.0089 | D65: 0.00976
A66: 9 | B66: 0.01018 | C66: 0.00902 | D66: 0.01646
A67: 12 | B67: 0.00592 | C67: 0.01096 | D67: 0.0139
A70: Beregnede feilverdier brukt til feilfelt - permanent vektendring
A71: Uke | B71: 20°C | D71: 40°C | F71: 60°C
B72: Maks - gj.snitt | C72: Gj.snitt - min | D72: Maks - gj.snitt | E72: Gj.snitt - min | F72: Maks - gj.snitt | G72: Gj.snitt - min
A73: 3 | B73: 0.00204 | C73: 0.00246 | D73: 0.00258 | E73: 0.00612 | F73: 0.0027 | G73: 0.0028
A74: 6 | B74: 0.0065 | C74: 0.0073 | D74: 0.0043 | E74: 0.0067 | F74: 0.00614 | G74: 0.00366
A75: 9 | B75: 0.01422 | C75: 0.01308 | D75: 0.00758 | E75: 0.00632 | F75: 0.00964 | G75: 0.01026
A76: 12 | B76: 0.00178 | C76: 0.00102 | D76: 0.00044 | E76: 0.00066 | F76: 0.0012 | G76: 0.0017

Sheet PETG - Prosent
A1: PETG – prosentberegninger
A3: Andel av vektopptaket som ble værende i materialet etter tørking
A5: Uke | B5: Temperatur | C5: Gj.snittlig vektendring (g) | D5: Gj.snittlig permanent endring (g) | E5: Permanent andel av opptak (%)
A7: 3 | B7: 20°C | C7: 0.0241 | D7: 0.0074 | E7: =SUM(D7/C7) -> 0.30705394
A8: 6 | B8: 20°C | C8: 0.025 | D8: 0.0074 | E8: =SUM(D8/C8) -> 0.296
A9: 9 | B9: 20°C | C9: 0.0264 | D9: 0.0102 | E9: =SUM(D9/C9) -> 0.38636364
A10: 12 | B10: 20°C | C10: 0.037 | D10: 0.0059 | E10: =SUM(D10/C10) -> 0.15945946
A11: 3 | B11: 40°C | C11: 0.0293 | D11: 0.0072 | E11: =SUM(D11/C11) -> 0.24573379
A12: 6 | B12: 40°C | C12: 0.0314 | D12: 0.0089 | E12: =SUM(D12/C12) -> 0.28343949
A13: 9 | B13: 40°C | C13: 0.0567 | D13: 0.009 | E13: =SUM(D13/C13) -> 0.15873016
A14: 12 | B14: 40°C | C14: 0.0473 | D14: 0.011 | E14: =SUM(D14/C14) -> 0.23255814
A15: 3 | B15: 60°C | C15: 0.038 | D15: 0.0142 | E15: =SUM(D15/C15) -> 0.37368421
A16: 6 | B16: 60°C | C16: 0.0429 | D16: 0.0098 | E16: =SUM(D16/C16) -> 0.22843823
A17: 9 | B17: 60°C | C17: 0.0445 | D17: 0.0165 | E17: =SUM(D17/C17) -> 0.37078652
A18: 12 | B18: 60°C | C18: 0.0506 | D18: 0.0127 | E18: =SUM(D18/C18) -> 0.25098814
A21: Uke | B21: 20°C | C21: 40°C | D21: 60°C
A22: 3 | B22: 0.30705394 | C22: 0.24573379 | D22: 0.37368421
A23: 6 | B23: 0.296 | C23: 0.28343949 | D23: 0.22843823
A24: 9 | B24: 0.38636364 | C24: 0.15873016 | D24: 0.37078652
A25: 12 | B25: 0.15945946 | C25: 0.23255814 | D25: 0.25098814

Sheet ASA - Vektregistrering
D2: Plasttype: ASA | H2: Første testpinne i hvert sett skal ikke skylles
B4: Dato | D4: 28/1
B6: Prøve ID | C6: Startvekt | D6: Prøve ID | E6: Startvekt
B7: C-0-1 | C7: 1.1818 | D7: C-0-2 | E7: 1.171
B8: C-0-1 | C8: 1.1695 | D8: C-0-2 | E8: 1.1734
B9: C-0-1 | C9: 1.1737 | D9: C-0-2 | E9: 1.1693
B10: C-0-1 | C10: 1.163 | D10: C-0-2 | E10: 1.1675
B11: C-0-1 | C11: 1.1684 | D11: C-0-2 | E11: 1.1849
B13: Temp 20C | L13: Temp 40C | V13: Temp 60C
B14: Tørr | G14: Våt | L14: Tørr | Q14: Våt | V14: Tørr | AA14: Våt
B15: Dato | C15: 27/1 | D15: 17/2 | E15: 18/2 | G15: Dato | H15: 27/1 | I15: 17/2 | L15: Dato | M15: 27/1 | N15: 17/2 | O15: 18/2 | Q15: Dato | R15: 27/1 | S15: 17/2 | V15: Dato | W15: 28/1 | X15: 17/2 | Y15: 18/2 | AA15: Dato | AB15: 28/1 | AC15: 17/2
B17: Prøve ID | C17: Startvekt | D17: Sluttvekt | E17: Tørrvekt | G17: Prøve ID | H17: Startvekt | I17: Sluttvekt | L17: Prøve ID | M17: Startvekt | N17: Sluttvekt | O17: Tørrvekt | Q17: Prøve ID | R17: Startvekt | S17: Sluttvekt | V17: Prøve ID | W17: Startvekt | X17: Sluttvekt | Y17: Tørrvekt | AA17: Prøve ID | AB17: Startvekt | AC17: Sluttvekt
A18: ikke skylt | B18: C-1-1 | C18: 1.1703 | D18: 1.1871 | E18: 1.1717 | F18: ikke skylt | G18: C-1-2 | H18: 1.1712 | I18: 1.1864 | K18: ikke skylt | L18: C-2-1 | M18: 1.1677 | N18: 1.2136 | O18: 1.1701 | P18: ikke skylt | Q18: C-2-2 | R18: 1.165 | S18: 1.1846 | U18: ikke skylt | V18: C-3-1 | W18: 1.1695 | X18: 1.1871 | Y18: 1.1721 | Z18: ikke skylt | AA18: C-3-2 | AB18: 1.1666 | AC18: 1.187
A19: skylt og tørket | B19: C-1-1 | C19: 1.1659 | D19: 1.1825 | E19: 1.1664 | F19: skylt og tørket | G19: C-1-2 | H19: 1.1727 | I19: 1.1889 | K19: skylt og tørket | L19: C-2-1 | M19: 1.1738 | N19: 1.209 | O19: 1.1846 | P19: skylt og tørket | Q19: C-2-2 | R19: 1.1683 | S19: 1.1966 | U19: skylt og tørket | V19: C-3-1 | W19: 1.167 | X19: 1.1914 | Y19: 1.1705 | Z19: skylt og tørket | AA19: C-3-2 | AB19: 1.1613 | AC19: 1.1811
A20: skylt og tørket | B20: C-1-1 | C20: 1.1713 | D20: 1.1864 | E20: 1.1715 | F20: skylt og tørket | G20: C-1-2 | H20: 1.1726 | I20: 1.2033 | K20: skylt og tørket | L20: C-2-1 | M20: 1.1785 | N20: 1.2275 | O20: 1.1823 | P20: skylt og tørket | Q20: C-2-2 | R20: 1.1737 | S20: 1.1875 | U20: skylt og tørket | V20: C-3-1 | W20: 1.1781 | X20: 1.1948 | Y20: 1.182 | Z20: skylt og tørket | AA20: C-3-2 | AB20: 1.1754 | AC20: 1.206
A21: skylt og tørket | B21: C-1-1 | C21: 1.1767 | D21: 1.1915 | E21: 1.1778 | F21: skylt og tørket | G21: C-1-2 | H21: 1.1648 | I21: 1.1818 | K21: skylt og tørket | L21: C-2-1 | M21: 1.1602 | N21: 1.2171 | O21: 1.163 | P21: skylt og tørket | Q21: C-2-2 | R21: 1.1716 | S21: 1.1867 | U21: skylt og tørket | V21: C-3-1 | W21: 1.1665 | X21: 1.1799 | Y21: 1.1685 | Z21: skylt og tørket | AA21: C-3-2 | AB21: 1.1561 | AC21: 1.1739
